Workbook

Sheet README
A1: Blockchain in Indian Government Administration: A Project-Level Dataset (2017–2026)
A2: Version 1.1.0 · created 2026-10-15 · licence CC BY 4.0 · authors: Santanu Mondal (ORCID 0009-0001-6243-1709) and T. Chithralekha, Pondicherry University
A3: DOI (all versions, always the latest): https://doi.org/10.5281/zenodo.23136332 · this version 1.1.0: https://doi.org/10.5281/zenodo.23415599
A5: Coded, source-linked inventory of blockchain / distributed-ledger initiatives by Indian public bodies (Union, all 28 States and 8 Union Territories, regulators, courts, statutory bodies), with dated lifecycle events, source-reported challenges (TOE-coded), evidence scores and a time series of the NIC blockchain platform. Structured as normalised tables with controlled vocabularies so new projects, events and snapshots can be added and validated.
A7: Sheets
A8: All projects – THE COMBINED TABLE: every project (Union, State, UT, district, municipal, PSU, regulator, court ...) in one row with level of government, body type, region, who built it, stage dates, NIC usage, challenges and evidence
A9: Summary – live counts by stage, tier, use-case and evidence score (formulas on the Projects sheet)
A10: Stage events – dated lifecycle events with sources (announced, pilot, live, scaled, latest update)
A11: Challenges – source-reported challenges, TOE-coded (see Vocabularies for TOE/DOI mapping)
A12: Sources / Project sources – all sources with type and evidence score, and which project each supports
A13: NIC snapshots – time series of the NIC blockchain platform by platform, application and department
A14: Jurisdictions – all 36 States/UTs with ISO 3166-2 and LGD codes, search results and live project counts
... A20: "Unclear" means no public update was found, not that a project failed.

Sheet Summary
A1: Summary (live formulas on the 'All projects' sheet; active records only)
A3: Stage | B3: Union | C3: State | D3: Union Territory | E3: District | F3: Municipal | G3: Total | H3: % of all
A4: Implemented | B4: =COUNTIFS('All projects'!$AB$2:$AB$119,$A4,'All projects'!$E$2:$E$119,B$3,'All projects'!$D$2:$D$119,"active") -> 19 | C4: =COUNTIFS('All projects'!$AB$2:$AB$119,$A4,'All projects'!$E$2:$E$119,C$3,'All projects'!$D$2:$D$119,"active") -> 23 | D4: =COUNTIFS('All projects'!$AB$2:$AB$119,$A4,'All projects'!$E$2:$E$119,D$3,'All projects'!$D$2:$D$119,"active") -> 5 | E4: =COUNTIFS('All projects'!$AB$2:$AB$119,$A4,'All projects'!$E$2:$E$119,E$3,'All projects'!$D$2:$D$119,"active") -> 2 | F4: =COUNTIFS('All projects'!$AB$2:$AB$119,$A4,'All projects'!$E$2:$E$119,F$3,'All projects'!$D$2:$D$119,"active") -> 1 | G4: =SUM(B4:F4) -> 50 | H4: =IF($G$10=0,0,G4/$G$10) -> 0.42735043
A5: In progress | B5: =COUNTIFS('All projects'!$AB$2:$AB$119,$A5,'All projects'!$E$2:$E$119,B$3,'All projects'!$D$2:$D$119,"active") -> 7 | C5: =COUNTIFS('All projects'!$AB$2:$AB$119,$A5,'All projects'!$E$2:$E$119,C$3,'All projects'!$D$2:$D$119,"active") -> 9 | D5: =COUNTIFS('All projects'!$AB$2:$AB$119,$A5,'All projects'!$E$2:$E$119,D$3,'All projects'!$D$2:$D$119,"active") -> 0 | E5: =COUNTIFS('All projects'!$AB$2:$AB$119,$A5,'All projects'!$E$2:$E$119,E$3,'All projects'!$D$2:$D$119,"active") -> 0 | F5: =COUNTIFS('All projects'!$AB$2:$AB$119,$A5,'All projects'!$E$2:$E$119,F$3,'All projects'!$D$2:$D$119,"active") -> 0 | G5: =SUM(B5:F5) -> 16 | H5: =IF($G$10=0,0,G5/$G$10) -> 0.13675214
A6: Proposed / Planned | B6: =COUNTIFS('All projects'!$AB$2:$AB$119,$A6,'All projects'!$E$2:$E$119,B$3,'All projects'!$D$2:$D$119,"active") -> 4 | C6: =COUNTIFS('All projects'!$AB$2:$AB$119,$A6,'All projects'!$E$2:$E$119,C$3,'All projects'!$D$2:$D$119,"active") -> 8 | D6: =COUNTIFS('All projects'!$AB$2:$AB$119,$A6,'All projects'!$E$2:$E$119,D$3,'All projects'!$D$2:$D$119,"active") -> 0 | E6: =COUNTIFS('All projects'!$AB$2:$AB$119,$A6,'All projects'!$E$2:$E$119,E$3,'All projects'!$D$2:$D$119,"active") -> 0 | F6: =COUNTIFS('All projects'!$AB$2:$AB$119,$A6,'All projects'!$E$2:$E$119,F$3,'All projects'!$D$2:$D$119,"active") -> 1 | G6: =SUM(B6:F6) -> 13 | H6: =IF($G$10=0,0,G6/$G$10) -> 0.11111111
A7: Pilot completed | B7: =COUNTIFS('All projects'!$AB$2:$AB$119,$A7,'All projects'!$E$2:$E$119,B$3,'All projects'!$D$2:$D$119,"active") -> 6 | C7: =COUNTIFS('All projects'!$AB$2:$AB$119,$A7,'All projects'!$E$2:$E$119,C$3,'All projects'!$D$2:$D$119,"active") -> 4 | D7: =COUNTIFS('All projects'!$AB$2:$AB$119,$A7,'All projects'!$E$2:$E$119,D$3,'All projects'!$D$2:$D$119,"active") -> 0 | E7: =COUNTIFS('All projects'!$AB$2:$AB$119,$A7,'All projects'!$E$2:$E$119,E$3,'All projects'!$D$2:$D$119,"active") -> 1 | F7: =COUNTIFS('All projects'!$AB$2:$AB$119,$A7,'All projects'!$E$2:$E$119,F$3,'All projects'!$D$2:$D$119,"active") -> 0 | G7: =SUM(B7:F7) -> 11 | H7: =IF($G$10=0,0,G7/$G$10) -> 0.094017094
A8: Unclear (no recent update) | B8: =COUNTIFS('All projects'!$AB$2:$AB$119,$A8,'All projects'!$E$2:$E$119,B$3,'All projects'!$D$2:$D$119,"active") -> 3 | C8: =COUNTIFS('All projects'!$AB$2:$AB$119,$A8,'All projects'!$E$2:$E$119,C$3,'All projects'!$D$2:$D$119,"active") -> 21 | D8: =COUNTIFS('All projects'!$AB$2:$AB$119,$A8,'All projects'!$E$2:$E$119,D$3,'All projects'!$D$2:$D$119,"active") -> 1 | E8: =COUNTIFS('All projects'!$AB$2:$AB$119,$A8,'All projects'!$E$2:$E$119,E$3,'All projects'!$D$2:$D$119,"active") -> 1 | F8: =COUNTIFS('All projects'!$AB$2:$AB$119,$A8,'All projects'!$E$2:$E$119,F$3,'All projects'!$D$2:$D$119,"active") -> 1 | G8: =SUM(B8:F8) -> 27 | H8: =IF($G$10=0,0,G8/$G$10) -> 0.23076923
A9: Discontinued | B9: =COUNTIFS('All projects'!$AB$2:$AB$119,$A9,'All projects'!$E$2:$E$119,B$3,'All projects'!$D$2:$D$119,"active") -> 0 | C9: =COUNTIFS('All projects'!$AB$2:$AB$119,$A9,'All projects'!$E$2:$E$119,C$3,'All projects'!$D$2:$D$119,"active") -> 0 | D9: =COUNTIFS('All projects'!$AB$2:$AB$119,$A9,'All projects'!$E$2:$E$119,D$3,'All projects'!$D$2:$D$119,"active") -> 0 | E9: =COUNTIFS('All projects'!$AB$2:$AB$119,$A9,'All projects'!$E$2:$E$119,E$3,'All projects'!$D$2:$D$119,"active") -> 0 | F9: =COUNTIFS('All projects'!$AB$2:$AB$119,$A9,'All projects'!$E$2:$E$119,F$3,'All projects'!$D$2:$D$119,"active") -> 0 | G9: =SUM(B9:F9) -> 0 | H9: =IF($G$10=0,0,G9/$G$10) -> 0
A10: Total | B10: =SUM(B4:B9) -> 39 | C10: =SUM(C4:C9) -> 65 | D10: =SUM(D4:D9) -> 6 | E10: =SUM(E4:E9) -> 4 | F10: =SUM(F4:F9) -> 3 | G10: =SUM(G4:G9) -> 117
A12: Pilot-to-production rate = Implemented ÷ (Implemented + Pilot completed + Unclear) | B12: =IFERROR(G4/(G4+G7+G8),0) -> 0.56818182
A13: Share backed by an official source (evidence score 4–5) | B13: =COUNTIFS('All projects'!$AX$2:$AX$119,">=4",'All projects'!$D$2:$D$119,"active")/$G$10 -> 0.61538462
A14: Mean evidence score | B14: =AVERAGEIFS('All projects'!$AX$2:$AX$119,'All projects'!$D$2:$D$119,"active") -> 3.8547009
A16: Type of public body | B16: Implemented | C16: All | D16: Implemented %
A17: Ministry / department | B17: =COUNTIFS('All projects'!$F$2:$F$119,$A17,'All projects'!$AB$2:$AB$119,"Implemented",'All projects'!$D$2:$D$119,"active") -> 24 | C17: =COUNTIFS('All projects'!$F$2:$F$119,$A17,'All projects'!$D$2:$D$119,"active") -> 50 | D17: =IF(C17=0,"",B17/C17) -> 0.48
A18: Government (whole of government) | B18: =COUNTIFS('All projects'!$F$2:$F$119,$A18,'All projects'!$AB$2:$AB$119,"Implemented",'All projects'!$D$2:$D$119,"active") -> 0 | C18: =COUNTIFS('All projects'!$F$2:$F$119,$A18,'All projects'!$D$2:$D$119,"active") -> 4 | D18: =IF(C18=0,"",B18/C18) -> 0
A19: IT / e-governance agency | B19: =COUNTIFS('All projects'!$F$2:$F$119,$A19,'All projects'!$AB$2:$AB$119,"Implemented",'All projects'!$D$2:$D$119,"active") -> 7 | C19: =COUNTIFS('All projects'!$F$2:$F$119,$A19,'All projects'!$D$2:$D$119,"active") -> 13 | D19: =IF(C19=0,"",B19/C19) -> 0.53846154
A20: Policy / planning body | B20: =COUNTIFS('All projects'!$F$2:$F$119,$A20,'All projects'!$AB$2:$AB$119,"Implemented",'All projects'!$D$2:$D$119,"active") -> 0 | C20: =COUNTIFS('All projects'!$F$2:$F$119,$A20,'All projects'!$D$2:$D$119,"active") -> 5 | D20: =IF(C20=0,"",B20/C20) -> 0
A21: PSU / state-owned company | B21: =COUNTIFS('All projects'!$F$2:$F$119,$A21,'All projects'!$AB$2:$AB$119,"Implemented",'All projects'!$D$2:$D$119,"active") -> 2 | C21: =COUNTIFS('All projects'!$F$2:$F$119,$A21,'All projects'!$D$2:$D$119,"active") -> 6 | D21: =IF(C21=0,"",B21/C21) -> 0.33333333
A22: Regulator / central bank | B22: =COUNTIFS('All projects'!$F$2:$F$119,$A22,'All projects'!$AB$2:$AB$119,"Implemented",'All projects'!$D$2:$D$119,"active") -> 2 | C22: =COUNTIFS('All projects'!$F$2:$F$119,$A22,'All projects'!$D$2:$D$119,"active") -> 7 | D22: =IF(C22=0,"",B22/C22) -> 0.28571429
A23: Court / judiciary | B23: =COUNTIFS('All projects'!$F$2:$F$119,$A23,'All projects'!$AB$2:$AB$119,"Implemented",'All projects'!$D$2:$D$119,"active") -> 2 | C23: =COUNTIFS('All projects'!$F$2:$F$119,$A23,'All projects'!$D$2:$D$119,"active") -> 4 | D23: =IF(C23=0,"",B23/C23) -> 0.5
A24: Election commission | B24: =COUNTIFS('All projects'!$F$2:$F$119,$A24,'All projects'!$AB$2:$AB$119,"Implemented",'All projects'!$D$2:$D$119,"active") -> 0 | C24: =COUNTIFS('All projects'!$F$2:$F$119,$A24,'All projects'!$D$2:$D$119,"active") -> 3 | D24: =IF(C24=0,"",B24/C24) -> 0
A25: Statutory board / authority | B25: =COUNTIFS('All projects'!$F$2:$F$119,$A25,'All projects'!$AB$2:$AB$119,"Implemented",'All projects'!$D$2:$D$119,"active") -> 5 | C25: =COUNTIFS('All projects'!$F$2:$F$119,$A25,'All projects'!$D$2:$D$119,"active") -> 11 | D25: =IF(C25=0,"",B25/C25) -> 0.45454545
A26: University / research institute | B26: =COUNTIFS('All projects'!$F$2:$F$119,$A26,'All projects'!$AB$2:$AB$119,"Implemented",'All projects'!$D$2:$D$119,"active") -> 4 | C26: =COUNTIFS('All projects'!$F$2:$F$119,$A26,'All projects'!$D$2:$D$119,"active") -> 6 | D26: =IF(C26=0,"",B26/C26) -> 0.66666667
A27: Society / foundation | B27: =COUNTIFS('All projects'!$F$2:$F$119,$A27,'All projects'!$AB$2:$AB$119,"Implemented",'All projects'!$D$2:$D$119,"active") -> 1 | C27: =COUNTIFS('All projects'!$F$2:$F$119,$A27,'All projects'!$D$2:$D$119,"active") -> 1 | D27: =IF(C27=0,"",B27/C27) -> 1
A28: District administration | B28: =COUNTIFS('All projects'!$F$2:$F$119,$A28,'All projects'!$AB$2:$AB$119,"Implemented",'All projects'!$D$2:$D$119,"active") -> 2 | C28: =COUNTIFS('All projects'!$F$2:$F$119,$A28,'All projects'!$D$2:$D$119,"active") -> 4 | D28: =IF(C28=0,"",B28/C28) -> 0.5
A29: Municipal body | B29: =COUNTIFS('All projects'!$F$2:$F$119,$A29,'All projects'!$AB$2:$AB$119,"Implemented",'All projects'!$D$2:$D$119,"active") -> 1 | C29: =COUNTIFS('All projects'!$F$2:$F$119,$A29,'All projects'!$D$2:$D$119,"active") -> 3 | D29: =IF(C29=0,"",B29/C29) -> 0.33333333
A31: Built by | B31: Implemented | C31: All | D31: Implemented %
A32: Government IT (NIC / C-DAC / NeGD) | B32: =COUNTIFS('All projects'!$Z$2:$Z$119,$A32,'All projects'!$AB$2:$AB$119,"Implemented",'All projects'!$D$2:$D$119,"active") -> 31 | C32: =COUNTIFS('All projects'!$Z$2:$Z$119,$A32,'All projects'!$D$2:$D$119,"active") -> 43 | D32: =IF(C32=0,"",B32/C32) -> 0.72093023
A33: State IT agency (in-house) | B33: =COUNTIFS('All projects'!$Z$2:$Z$119,$A33,'All projects'!$AB$2:$AB$119,"Implemented",'All projects'!$D$2:$D$119,"active") -> 1 | C33: =COUNTIFS('All projects'!$Z$2:$Z$119,$A33,'All projects'!$D$2:$D$119,"active") -> 5 | D33: =IF(C33=0,"",B33/C33) -> 0.2
A34: Private technology vendor | B34: =COUNTIFS('All projects'!$Z$2:$Z$119,$A34,'All projects'!$AB$2:$AB$119,"Implemented",'All projects'!$D$2:$D$119,"active") -> 9 | C34: =COUNTIFS('All projects'!$Z$2:$Z$119,$A34,'All projects'!$D$2:$D$119,"active") -> 30 | D34: =IF(C34=0,"",B34/C34) -> 0.3
A35: Academic / research partner | B35: =COUNTIFS('All projects'!$Z$2:$Z$119,$A35,'All projects'!$AB$2:$AB$119,"Implemented",'All projects'!$D$2:$D$119,"active") -> 3 | C35: =COUNTIFS('All projects'!$Z$2:$Z$119,$A35,'All projects'!$D$2:$D$119,"active") -> 8 | D35: =IF(C35=0,"",B35/C35) -> 0.375
A36: Banks, depositories or telecom operators | B36: =COUNTIFS('All projects'!$Z$2:$Z$119,$A36,'All projects'!$AB$2:$AB$119,"Implemented",'All projects'!$D$2:$D$119,"active") -> 2 | C36: =COUNTIFS('All projects'!$Z$2:$Z$119,$A36,'All projects'!$D$2:$D$119,"active") -> 6 | D36: =IF(C36=0,"",B36/C36) -> 0.33333333
A37: Government–industry consortium | B37: =COUNTIFS('All projects'!$Z$2:$Z$119,$A37,'All projects'!$AB$2:$AB$119,"Implemented",'All projects'!$D$2:$D$119,"active") -> 3 | C37: =COUNTIFS('All projects'!$Z$2:$Z$119,$A37,'All projects'!$D$2:$D$119,"active") -> 4 | D37: =IF(C37=0,"",B37/C37) -> 0.75
A38: International organisation | B38: =COUNTIFS('All projects'!$Z$2:$Z$119,$A38,'All projects'!$AB$2:$AB$119,"Implemented",'All projects'!$D$2:$D$119,"active") -> 0 | C38: =COUNTIFS('All projects'!$Z$2:$Z$119,$A38,'All projects'!$D$2:$D$119,"active") -> 2 | D38: =IF(C38=0,"",B38/C38) -> 0
A39: Not applicable (policy or judgment) | B39: =COUNTIFS('All projects'!$Z$2:$Z$119,$A39,'All projects'!$AB$2:$AB$119,"Implemented",'All projects'!$D$2:$D$119,"active") -> 0 | C39: =COUNTIFS('All projects'!$Z$2:$Z$119,$A39,'All projects'!$D$2:$D$119,"active") -> 2 | D39: =IF(C39=0,"",B39/C39) -> 0
A40: Not disclosed | B40: =COUNTIFS('All projects'!$Z$2:$Z$119,$A40,'All projects'!$AB$2:$AB$119,"Implemented",'All projects'!$D$2:$D$119,"active") -> 1 | C40: =COUNTIFS('All projects'!$Z$2:$Z$119,$A40,'All projects'!$D$2:$D$119,"active") -> 17 | D40: =IF(C40=0,"",B40/C40) -> 0.058823529
A42: Region | B42: Implemented | C42: All | D42: Implemented %
A43: Northern | B43: =COUNTIFS('All projects'!$M$2:$M$119,$A43,'All projects'!$AB$2:$AB$119,"Implemented",'All projects'!$D$2:$D$119,"active") -> 4 | C43: =COUNTIFS('All projects'!$M$2:$M$119,$A43,'All projects'!$D$2:$D$119,"active") -> 10 | D43: =IF(C43=0,"",B43/C43) -> 0.4
A44: Central | B44: =COUNTIFS('All projects'!$M$2:$M$119,$A44,'All projects'!$AB$2:$AB$119,"Implemented",'All projects'!$D$2:$D$119,"active") -> 4 | C44: =COUNTIFS('All projects'!$M$2:$M$119,$A44,'All projects'!$D$2:$D$119,"active") -> 11 | D44: =IF(C44=0,"",B44/C44) -> 0.36363636
A45: Eastern | B45: =COUNTIFS('All projects'!$M$2:$M$119,$A45,'All projects'!$AB$2:$AB$119,"Implemented",'All projects'!$D$2:$D$119,"active") -> 2 | C45: =COUNTIFS('All projects'!$M$2:$M$119,$A45,'All projects'!$D$2:$D$119,"active") -> 9 | D45: =IF(C45=0,"",B45/C45) -> 0.22222222
...

Sheet All projects
A1: project_id | B1: project_name | C1: description | D1: record_status | E1: government_level | F1: body_category | G1: implementing_body | H1: parent_ministry_or_state | I1: dataset_group | J1: jurisdiction_id | K1: state_ut | L1: jurisdiction_type | M1: region | N1: lgd_code | O1: domain | P1: cofog_division | Q1: cofog_label | R1: use_case | S1: problem | T1: service_type | U1: platform_reported | V1: platform | W1: platform_family | X1: chain_type | Y1: tech_partner | Z1: implementation_model | AA1: is_nic_chain | AB1: stage | AC1: stage_generic | AD1: status_text | AE1: status_as_of | AF1: start_year | AG1: date_announced | AH1: date_pilot_started | AI1: date_pilot_completed | AJ1: date_live | AK1: date_scaled | AL1: date_discontinued | AM1: date_latest_update | AN1: months_to_live | AO1: years_since_update | AP1: scale_text | AQ1: scale_tier | AR1: nic_documents_latest | AS1: nic_verifications_latest | AT1: nic_snapshot_date | AU1: challenge_codes | AV1: toe_dimensions | AW1: n_challenges | AX1: evidence_score | AY1: evidence_label | AZ1: n_sources | BA1: n_official_sources | BB1: primary_source_url | BC1: verify_note | BD1: related_projects | BE1: last_reviewed
A2: C01 | B2: National Blockchain Framework – Vishvasya Blockchain Stack (BaaS) | C2: Shared permissioned blockchain service for all departments; nodes at NIC data centres Bhubaneswar, Pune, Hyderabad | D2: active | E2: Union | F2: IT / e-governance agency | G2: MeitY / NIC | H2: Ministry of Electronics & IT | I2: Union government | J2: IN | K2: Union / national | L2: National | M2: National | O2: Platform & Infrastructure | P2: 1 | Q2: General public services | R2: Platform / ecosystem | S2: Capacity & shared infrastructure | T2: G2G | U2: Permissioned (NIC) | V2: NIC chains (Hyperledger-based) | W2: Hyperledger family | X2: Permissioned | Y2: NIC, C-DAC | Z2: Government IT (NIC / C-DAC / NeGD) | AA2: Yes | AB2: Implemented | AC2: Live | AD2: Live. NIC dashboard: 6 products, 12 central orgs/states, 22 departments, 4 PoCs | AE2: 2026-10-03 | AF2: 2021 | AG2: 2021-03 | AJ2: 2024-09-04 | AM2: 2026-10-03 | AN2: 42 | AO2: 0.0 | AP2: 11,25,46,175 documents; 47,13,59,890 verifications; outlay ₹64.76 crore | AQ2: Large (≥10 lakh) | AU2: O2;O3 | AV2: Organisation | AW2: 2 | AX2: 5 | AY2: 5 – Official source with live/current data | AZ2: 7 | BA2: 4 | BB2: https://blockchain.gov.in/Home/Home | BE2: 2026-10-15
A3: C02 | B3: NBFLite – blockchain sandbox | C3: Sandbox with smart-contract templates for startups, academia, students | D3: active | E3: Union | F3: Ministry / department | G3: MeitY | H3: Ministry of Electronics & IT | I3: Union government | J3: IN | K3: Union / national | L3: National | M3: National | O3: Platform & Infrastructure | P3: 1 | Q3: General public services | R3: Platform / ecosystem | S3: Capacity & shared infrastructure | T3: G2B | U3: Permissioned | V3: NIC chains (Hyperledger-based) | W3: Hyperledger family | X3: Permissioned | Y3: NIC | Z3: Government IT (NIC / C-DAC / NeGD) | AA3: Yes | AB3: Implemented | AC3: Live | AD3: Live | AE3: 2025-10-24 | AF3: 2024 | AJ3: 2024-09-04 | AM3: 2025-10-24 | AO3: 1.0 | AQ3: Not reported | AW3: 0 | AX3: 5 | AY3: 5 – Official source with live/current data | AZ3: 4 | BA3: 3 | BB3: https://www.pib.gov.in/PressReleasePage.aspx?PRID=2182023 | BE3: 2026-10-15
A4: C03 | B4: Praamaanik – mobile app verification | C4: Checks a mobile app's origin against blockchain records; verified via M-Kavach-2 app | D4: active | E4: Union | F4: Ministry / department | G4: MeitY | H4: Ministry of Electronics & IT | I4: Union government | J4: IN | K4: Union / national | L4: National | M4: National | O4: Telecom & Cyber | P4: 4 | Q4: Economic affairs | R4: Authentication & anti-fraud | S4: Fraud / spam / fake apps | T4: G2C | U4: Permissioned | V4: NIC chains (Hyperledger-based) | W4: Hyperledger family | X4: Permissioned | Y4: NIC; MPSEDC apps onboarded | Z4: Government IT (NIC / C-DAC / NeGD) | AA4: Yes | AB4: Implemented | AC4: Live | AD4: Live; 14 citizen apps of MPSEDC onboarded | AE4: 2026-03-27 | AF4: 2024 | AJ4: 2024-09-04 | AM4: 2026-03-27 | AO4: 0.6 | AP4: 14 apps | AQ4: Small (<10,000) | AW4: 0 | AX4: 5 | AY4: 5 – Official source with live/current data | AZ4: 5 | BA4: 4 | BB4: https://www.pib.gov.in/PressReleasePage.aspx?PRID=2246221&reg=3&lang=1 | BE4: 2026-10-15
A5: C04 | B5: Blockchain India Challenge / Startup Challenge (Blockchain & Web3) | C5: Stage-wise funding for startups building permissioned govt blockchain apps in 10 domains (e-procurement, supply chain, PDS, education, health, agriculture, power, IoT, land records, environment) | D5: active | E5: Union | F5: Ministry / department | G5: MeitY with C-DAC | H5: Ministry of Electronics & IT | I5: Union government | J5: IN | K5: Union / national | L5: National | M5: National | O5: Platform & Infrastructure | P5: 1 | Q5: General public services | R5: Platform / ecosystem | S5: Capacity & shared infrastructure | T5: G2B | U5: Permissioned (NBF) | V5: NIC chains (Hyperledger-based) | W5: Hyperledger family | X5: Permissioned | Y5: C-DAC, DPIIT | Z5: Government IT (NIC / C-DAC / NeGD) | AA5: Yes | AB5: In progress | AC5: In development | AD5: Call open; staged grants up to ₹50 lakh per team | AE5: 2026-03-27 | AF5: 2026 | AG5: 2026-02-23 | AM5: 2026-03-27 | AO5: 0.6 | AP5: Up to 40/30/20/10 teams by stage | AQ5: Not reported | AW5: 0 | AX5: 5 | AY5: 5 – Official source with live/current data | AZ5: 7 | BA5: 3 | BB5: https://www.pib.gov.in/PressReleasePage.aspx?PRID=2246221&reg=3&lang=1 | BE5: 2026-10-15
A6: C05 | B6: CoE in Blockchain Technology + Blockchain-as-a-Service | C6: Consultancy, training, PoCs; runs NIC chains and BaaS (hosting, smart contracts, security) for departments | D6: active | E6: Union | F6: IT / e-governance agency | G6: NIC – Centre of Excellence in Blockchain (Bengaluru) | H6: Ministry of Electronics & IT | I6: Union government | J6: IN | K6: Union / national | L6: National | M6: National | O6: Platform & Infrastructure | P6: 1 | Q6: General public services | R6: Platform / ecosystem | S6: Capacity & shared infrastructure | T6: G2G | U6: Hyperledger Fabric, Hyperledger Sawtooth, Ethereum | V6: Hyperledger Fabric | W6: Hyperledger family | X6: Permissioned | Y6: — | Z6: Government IT (NIC / C-DAC / NeGD) | AA6: No | AB6: Implemented | AC6: Live | AD6: Operational | AE6: 2026-10-03 | AF6: 2019 | AG6: 2020-01-17 | AJ6: 2020-01-18 | AK6: 2024-09-04 | AM6: 2026-10-03 | AN6: 0 | AO6: 0.0 | AP6: Growth: Jun 2024 8.08 crore docs (9 orgs, 19 depts) → Dec 2025 10.38 crore (10, 21) → Oct 2026 11.25 crore (12, 22) | AQ6: Large (≥10 lakh) | AU6: O1;O2;T2 | AV6: Organisation;Technology | AW6: 3 | AX6: 5 | AY6: 5 – Official source with live/current data | AZ6: 10 | BA6: 5 | BB6: https://blockchain.gov.in/Home/Home | BE6: 2026-10-15
A7: C06 | B7: Document Chain | C7: Store/verify caste, income, ration card, driving licence, birth & death certificates | D7: active | E7: Union | F7: IT / e-governance agency | G7: NIC | H7: Ministry of Electronics & IT | I7: Union government | J7: IN | K7: Union / national | L7: National | M7: National | O7: Certificates & Identity | P7: 1 | Q7: General public services | R7: Certificates & identity | S7: Forgery / fake documents | T7: G2C | U7: Permissioned (NIC) | V7: NIC chains (Hyperledger-based) | W7: Hyperledger family | X7: Permissioned | Y7: — | Z7: Government IT (NIC / C-DAC / NeGD) | AA7: Yes | AB7: Implemented | AC7: Live | AD7: Live | AE7: 2026-10-03 | AF7: 2020 | AJ7: 2024-04 | AM7: 2026-10-03 | AO7: 0.0 | AP7: 48,000+ documents | AQ7: Medium (10,000–10 lakh) | AW7: 0 | AX7: 5 | AY7: 5 – Official source with live/current data | AZ7: 7 | BA7: 5 | BB7: https://www.pib.gov.in/PressReleasePage.aspx?PRID=2182023 | BE7: 2026-10-15
A8: C07 | B8: Property Chain | C8: Records every property transaction; full history visible before purchase | D8: active | E8: Union | F8: IT / e-governance agency | G8: NIC | H8: Ministry of Electronics & IT | I8: Union government | J8: IN | K8: Union / national | L8: National | M8: National | O8: Land & Property | P8: 1 | Q8: General public services | R8: Land / property registry | S8: Land fraud & disputes | T8: G2C | U8: Permissioned (NIC) | V8: NIC chains (Hyperledger-based) | W8: Hyperledger family | X8: Permissioned | Y8: — | Z8: Government IT (NIC / C-DAC / NeGD) | AA8: Yes | AB8: Implemented | AC8: Live | AD8: Live | AE8: 2026-10-03 | AF8: 2020 | AJ8: 2025-10-21 | AM8: 2026-10-03 | AO8: 0.0 | AP8: 34 crore+ property documents (per PIB) | AQ8: Large (≥10 lakh) | AW8: 0 | AX8: 5 | AY8: 5 – Official source with live/current data | AZ8: 6 | BA8: 5 | BB8: https://www.pib.gov.in/PressReleasePage.aspx?PRID=2182023 | BC8: PIB gives 34 crore for both total and property – confirm | BE8: 2026-10-15
A9: C08 | B9: Judiciary Chain | C9: Supreme Court bail and judgment orders recorded; proposed uses: judicial deposits, FIR/charge-sheet transfer, e-summons | D9: active | E9: Union | F9: Court / judiciary | G9: NIC with Supreme Court of India | H9: Ministry of Law & Justice / Judiciary | I9: Union government | J9: IN | K9: Union / national | L9: National | M9: National | O9: Justice & Police | P9: 3 | Q9: Public order and safety | R9: Records & audit trail | S9: Tampering of records | T9: G2G | U9: Permissioned (NIC) | V9: NIC chains (Hyperledger-based) | W9: Hyperledger family | X9: Permissioned | Y9: — | Z9: Government IT (NIC / C-DAC / NeGD) | AA9: Yes | AB9: Implemented | AC9: Live | AD9: Live (Supreme Court) | AE9: 2026-10-14 | AF9: 2023 | AJ9: 2023-11-13 | AM9: 2026-10-14 | AO9: 0.0 | AP9: 447 documents; 987 verifications (NIC statistics, 2026-10-14) | AQ9: Small (<10,000) | AR9: 447 | AS9: 987 | AT9: 2026-10-14 | AW9: 0 | AX9: 5 | AY9: 5 – Official source with live/current data | AZ9: 6 | BA9: 4 | BB9: https://blockchain.gov.in/Home/Home | BE9: 2026-10-15
A10: C09 | B10: Inter-operable Criminal Justice System chain | C10: Links police, forensic and court records; live for High Court of Karnataka | D10: active | E10: Union | F10: Court / judiciary | G10: NIC – ICJS with High Court of Karnataka | H10: Ministry of Home Affairs / Judiciary | I10: Union government | J10: IN | K10: Union / national | L10: National | M10: National | O10: Justice & Police | P10: 3 | Q10: Public order and safety | R10: Records & audit trail | S10: Tampering of records | T10: G2G | U10: Permissioned (NIC) | V10: NIC chains (Hyperledger-based) | W10: Hyperledger family | X10: Permissioned | Y10: — | Z10: Government IT (NIC / C-DAC / NeGD) | AA10: Yes | AB10: Implemented | AC10: Live | AD10: Live; grew from 39,000 docs (Oct 2025) to 17.4 lakh | AE10: 2026-10-14 | AF10: 2022 | AJ10: 2025-10 | AM10: 2026-10-14 | AO10: 0.0 | AP10: 17,41,654 documents; 21,62,694 verifications (NIC statistics, 2026-10-14) | AQ10: Large (≥10 lakh) | AR10: 1741654 | AS10: 2162694 | AT10: 2026-10-14 | AW10: 0 | AX10: 5 | AY10: 5 – Official source with live/current data | AZ10: 4 | BA10: 4 | BB10: https://blockchain.gov.in/Home/Home | BE10: 2026-10-15
A11: C10 | B11: NIC PoCs: Assam land records, Blood Bank chain, GST Chain, PDS chain | C11: Blood bank: safe-blood and donor traceability; GST: running tax liability ledger; PDS: grain from MSP procurement to ration card | D11: active | E11: Union | F11: IT / e-governance agency | G11: MeitY / NIC | H11: Ministry of Electronics & IT | I11: Union government | J11: IN | K11: Union / national | L11: National | M11: National | O11: Platform & Infrastructure | P11: 1 | Q11: General public services | R11: Platform / ecosystem | S11: Capacity & shared infrastructure | T11: G2G | U11: Permissioned (NIC) | V11: NIC chains (Hyperledger-based) | W11: Hyperledger family | X11: Permissioned | Y11: NIC | Z11: Government IT (NIC / C-DAC / NeGD) | AA11: Yes | AB11: Proposed / Planned | AC11: Planned | AD11: Listed as PoCs on NIC dashboard | AE11: 2026-10-03 | AF11: 2023 | AG11: 2023 | AM11: 2026-10-03 | AO11: 0.0 | AP11: 4 PoCs | AQ11: Not reported | AW11: 0 | AX11: 5 | AY11: 5 – Official source with live/current data | AZ11: 7 | BA11: 6 | BB11: https://blockchain.gov.in/Home/Home | BE11: 2026-10-15
A12: C11 | B12: Legal Metrology approvals on NIC Document Chain | C12: Packaged commodity registration, weights & measures approvals, importer certificates | D12: active | E12: Union | F12: Ministry / department | G12: Dept of Consumer Affairs – Legal Metrology | H12: Ministry of Consumer Affairs, Food & PD | I12: Union government | J12: IN | K12: Union / national | L12: National | M12: National | O12: Certificates & Identity | P12: 1 | Q12: General public services | R12: Certificates & identity | S12: Forgery / fake documents | T12: G2B | U12: Permissioned (NIC) | V12: NIC chains (Hyperledger-based) | W12: Hyperledger family | X12: Permissioned | Y12: NIC | Z12: Government IT (NIC / C-DAC / NeGD) | AA12: Yes | AB12: Implemented | AC12: Live | AD12: Live | AE12: 2026-10-14 | AF12: 2023 | AJ12: 2023 | AM12: 2026-10-14 | AO12: 0.0 | AP12: 23,047 documents; 16 verifications (NIC statistics, 2026-10-14) | AQ12: Medium (10,000–10 lakh) | AR12: 23047 | AS12: 16 | AT12: 2026-10-14 | AW12: 0 | AX12: 5 | AY12: 5 – Official source with live/current data | AZ12: 4 | BA12: 2 | BB12: https://blockchain.gov.in/Home/Home | BE12: 2026-10-15
A13: C12 | B13: Skill documents on NIC Document Chain | C13: Rural skills (training) documents recorded for verification | D13: active | E13: Union | F13: Ministry / department | G13: Ministry of Rural Development – Rural Skills Division | H13: Ministry of Rural Development | I13: Union government | J13: IN | K13: Union / national | L13: National | M13: National | O13: Education & Skills | P13: 9 | Q13: Education | R13: Certificates & identity | S13: Forgery / fake documents | T13: G2C | U13: Permissioned (NIC) | V13: NIC chains (Hyperledger-based) | W13: Hyperledger family | X13: Permissioned | Y13: NIC | Z13: Government IT (NIC / C-DAC / NeGD) | AA13: Yes | AB13: Implemented | AC13: Live | AD13: Live (small scale) | AE13: 2026-10-14 | AJ13: 2026-10-03 | AM13: 2026-10-14 | AO13: 0.0 | AP13: 4,553 documents; 1,702 verifications (NIC statistics, 2026-10-14) | AQ13: Small (<10,000) | AR13: 4553 | AS13: 1702 | AT13: 2026-10-14 | AW13: 0 | AX13: 5 | AY13: 5 – Official source with live/current data | AZ13: 4 | BA13: 2 | BB13: https://blockchain.gov.in/Home/Home | BC13: Confirm which scheme (e.g. DDU-GKY) | BE13: 2026-10-15
A14: C13 | B14: CBDC-based DBT for food subsidy (PMGKAY) | C14: Programmable e₹ in beneficiary wallets, redeemable for wheat/rice at authorised shops | D14: active | E14: Union | F14: Ministry / department | G14: Dept of Food & Public Distribution with RBI, PFMS, Canara Bank | H14: Ministry of Consumer Affairs, Food & PD | I14: Union government | J14: IN | K14: Union / national | L14: National | M14: National | O14: Welfare & Subsidy | P14: 10 | Q14: Social protection | R14: Welfare delivery | S14: Leakage / beneficiary fraud | T14: G2C | U14: CBDC (e₹) – DLT use not confirmed by RBI | V14: RBI CBDC infrastructure | W14: CBDC infrastructure | X14: CBDC (DLT not confirmed) | Y14: RBI, Canara Bank | Z14: Banks, depositories or telecom operators | AA14: No | AB14: In progress | AC14: In development | AD14: Rolling out; full coverage of eligible beneficiaries in Chandigarh & DNH | AE14: 2026-08-14 | AF14: 2026 | AH14: 2026-02 | AJ14: 2026-08-14 | AM14: 2026-08-14 | AN14: 6 | AO14: 0.2 | AP14: Target: 80 crore PDS beneficiaries nationally | AQ14: Not reported | AW14: 0 | AX14: 5 | AY14: 5 – Official source with live/current data | AZ14: 4 | BA14: 1 | BB14: https://www.pib.gov.in/PressReleseDetailm.aspx?PRID=2233186&reg=3&lang=1 | BC14: Treat as digital currency, not proven blockchain | BE14: 2026-10-15
A15: C14 | B15: Blockchain solutions with NIC (details not public) | C15: Named by MeitY as developing blockchain solutions | D15: active | E15: Union | F15: Ministry / department | G15: Ministry of Corporate Affairs | H15: Ministry of Corporate Affairs | I15: Union government | J15: IN | K15: Union / national | L15: National | M15: National | O15: Grievance & Records | P15: 1 | Q15: General public services | R15: Platform / ecosystem | S15: Capacity & shared infrastructure | T15: G2G | U15: Not disclosed | V15: Not disclosed | W15: Not disclosed | X15: Not disclosed | Y15: NIC | Z15: Government IT (NIC / C-DAC / NeGD) | AA15: No | AB15: In progress | AC15: In development | AD15: Development stage | AE15: 2024-12-16 | AF15: 2024 | AG15: 2024 | AM15: 2024-12-16 | AO15: 1.8 | AQ15: Not reported | AW15: 0 | AX15: 3 | AY15: 3 – Mainstream news | AZ15: 1 | BA15: 0 | BB15: https://www.medianama.com/2024/12/223-blockchain-land-use-pilot-karnataka-jharkhandd/ | BC15: Scope not public | BE15: 2026-10-15
A16: C15 | B16: Kasturi Cotton Bharat – blockchain traceability | C16: QR certification at each stage plus blockchain platform for end-to-end traceability and transaction certificates | D16: active | E16: Union | F16: Ministry / department | G16: Ministry of Textiles – Cotton Corporation of India & TEXPROCIL | H16: Ministry of Textiles | I16: Union government | J16: IN | K16: Union / national | L16: National | M16: National | O16: Agriculture & Trade | P16: 4 | Q16: Economic affairs | R16: Supply-chain traceability | S16: Lack of traceability / counterfeits | T16: G2B | U16: Not disclosed | V16: Not disclosed | W16: Not disclosed | X16: Not disclosed | Y16: CCI, TEXPROCIL | Z16: Not disclosed | AA16: No | AB16: Implemented | AC16: Live | AD16: Operational nationwide | AE16: 2026-08-06 | AF16: 2022 | AG16: 2022-12-15 | AJ16: 2024-08-06 | AM16: 2026-08-06 | AN16: 20 | AO16: 0.2 | AP16: ₹30 crore budget; 343 ginning units registered | AQ16: Not reported | AW16: 0 | AX16: 5 | AY16: 5 – Official source with live/current data | AZ16: 8 | BA16: 2 | BB16: https://www.pib.gov.in/PressReleasePage.aspx?PRID=2042089 | BE16: 2026-10-15
A17: C16 | B17: PM Rashtriya Bal Puraskar certificates on blockchain | C17: Award certificates issued as blockchain digital certificates (IIT Kanpur National Blockchain Project) | D17: active | E17: Union | F17: Ministry / department | G17: Ministry of Women & Child Development | H17: Ministry of Women & Child Development | I17: Union government | J17: IN | K17: Union / national | L17: National | M17: National | O17: Certificates & Identity | P17: 1 | Q17: General public services | R17: Certificates & identity | S17: Forgery / fake documents | T17: G2C | U17: IIT Kanpur NBP platform | V17: IIT Kanpur NBP | W17: Other enterprise DLT | X17: Not disclosed | Y17: IIT Kanpur, CRUBN | Z17: Academic / research partner | AA17: No | AB17: Implemented | AC17: Live | AD17: Issued digitally for 2021 & 2022 awards | AE17: 2022-01-24 | AF17: 2022 | AG17: 2022-01-21 | AJ17: 2022-01-24 | AM17: 2022-01-24 | AN17: 0 | AO17: 4.7 | AP17: 61 awardees | AQ17: Small (<10,000) | AW17: 0 | AX17: 4 | AY17: 4 – Official document (govt site, PIB, tender, court) | AZ17: 5 | BA17: 4 | BB17: https://www.pib.gov.in/PressReleaseIframePage.aspx?PRID=1792136 | BE17: 2026-10-15
A18: C17 | B18: Blockchain-based tamper-proof railway signalling | C18: Distributed ledger for signal records and smart-contract automation | D18: active | E18: Union | F18: Ministry / department | G18: Ministry of Railways with IIT Kharagpur & IIT Bhubaneswar | H18: Ministry of Railways | I18: Union government | J18: IN | K18: Union / national | L18: National | M18: National | O18: Transport | P18: 4 | Q18: Economic affairs | R18: Records & audit trail | S18: Tampering of records | T18: G2G | U18: Not stated | V18: Not disclosed | W18: Not disclosed | X18: Not disclosed | Y18: IIT KGP, IIT BBS | Z18: Academic / research partner | AA18: No | AB18: Proposed / Planned | AC18: Planned | AD18: Under development / testing; approved by Railway Minister | AE18: 2023-07-11 | AF18: 2023 | AG18: 2023-06 | AM18: 2023-07-11 | AO18: 3.3 | AQ18: Not reported | AW18: 0 | AX18: 3 | AY18: 3 – Mainstream news | AZ18: 3 | BA18: 0 | BB18: https://www.freepressjournal.in/education/iit-kharagpur-developing-tamper-proof-signalling-system-for-safety-of-trains | BE18: 2026-10-15
A19: C18 | B19: Fertilizer subsidy supply-chain pilot (GNFC) | C19: Automated quantity certification and claims to cut subsidy reimbursement time | D19: active | E19: Union | F19: Policy / planning body | G19: NITI Aayog | H19: NITI Aayog | I19: Union government | J19: IN | K19: Union / national | L19: National | M19: National | O19: Welfare & Subsidy | P19: 10 | Q19: Social protection | R19: Welfare delivery | S19: Leakage / beneficiary fraud | T19: G2B | U19: Not stated | V19: Not disclosed | W19: Not disclosed | X19: Not disclosed | Y19: PwC, Intel, GNFC | Z19: Private technology vendor | AA19: No | AB19: Pilot completed | AC19: Pilot completed | AD19: PoC done; lessons published | AE19: 2020-01 | AF19: 2019 | AG19: 2018-06-29 | AI19: 2020-01 | AM19: 2020-01 | AO19: 6.7 | AQ19: Not reported | AU19: T1 | AV19: Technology | AW19: 1 | AX19: 4 | AY19: 4 – Official document (govt site, PIB, tender, court) | AZ19: 2 | BA19: 2 | BB19: https://www.niti.gov.in/sites/default/files/2020-01/Blockchain_The_India_Strategy_Part_I.pdf | BE19: 2026-10-15
A20: C19 | B20: Drug supply chain pilot (blockchain + IoT) | C20: Track drugs from manufacturer to patient to stop fake medicines | D20: active | E20: Union | F20: Policy / planning body | G20: NITI Aayog | H20: NITI Aayog | I20: Union government | J20: IN | K20: Union / national | L20: National | M20: National | O20: Health & Supply Chain | P20: 7 | Q20: Health | R20: Supply-chain traceability | S20: Lack of traceability / counterfeits | T20: G2B | U20: Oracle Blockchain | V20: Oracle Blockchain | W20: Other enterprise DLT | X20: Permissioned | Y20: Oracle, Apollo Hospitals, Strides Pharma | Z20: Private technology vendor | AA20: No | AB20: Pilot completed | AC20: Pilot completed | AD20: Pilot executed (reported in NITI Aayog draft strategy, Jan 2020); no follow-up found | AE20: 2020-01 | AF20: 2018 | AG20: 2018-09-28 | AI20: 2020-01 | AM20: 2020-01 | AO20: 6.7 | AQ20: Not reported | AU20: E2;T1;T2 | AV20: Environment;Technology | AW20: 3 | AX20: 4 | AY20: 4 – Official document (govt site, PIB, tender, court) | AZ20: 3 | BA20: 2 | BB20: https://www.niti.gov.in/sites/default/files/2020-01/Blockchain_The_India_Strategy_Part_I.pdf | BC20: v1.1: official PIB release (Sep 2018) and NITI Aayog draft strategy (Jan 2020) found; the strategy reports the pilot as executed. | BE20: 2026-10-15
A21: C20 | B21: IndiaChain – national blockchain network | C21: Proposed common national blockchain infrastructure | D21: active | E21: Union | F21: Policy / planning body | G21: NITI Aayog | H21: NITI Aayog | I21: Union government | J21: IN | K21: Union / national | L21: National | M21: National | O21: Platform & Infrastructure | P21: 1 | Q21: General public services | R21: Platform / ecosystem | S21: Capacity & shared infrastructure | T21: G2G | U21: Not stated | V21: Not disclosed | W21: Not disclosed | X21: Not disclosed | Y21: — | Z21: Not disclosed | AA21: No | AB21: Unclear (no recent update) | AC21: Unclear | AD21: No separate launch; idea later taken up by MeitY's NBF | AE21: 2022-10-18 | AF21: 2018 | AG21: 2017-11-13 | AM21: 2022-10-18 | AO21: 4.0 | AQ21: Not reported | AU21: E1;T3 | AV21: Environment;Technology | AW21: 2 | AX21: 4 | AY21: 4 – Official document (govt site, PIB, tender, court) | AZ21: 3 | BA21: 1 | BB21: https://www.investindia.gov.in/team-india-blogs/implementing-blockchain-india | BE21: 2026-10-15
A22: O01 | B22: Digital Rupee – wholesale (e₹-W) and retail (e₹-R) CBDC | C22: CBDC pilots: wholesale for govt securities; retail token wallets via banks; offline and programmable features | D22: active | E22: Union | F22: Regulator / central bank | G22: Reserve Bank of India | H22: Central bank | I22: Other public body | J22: IN | K22: Union / national | L22: National | M22: National | O22: Finance & Payments | P22: 4 | Q22: Economic affairs | R22: CBDC / digital payments | S22: Payment efficiency & programmability | T22: G2C | U22: Not publicly confirmed as DLT | V22: RBI CBDC infrastructure | W22: CBDC infrastructure | X22: CBDC (DLT not confirmed) | Y22: Pilot banks & non-banks | Z22: Banks, depositories or telecom operators | AA22: No | AB22: In progress | AC22: In development | AD22: Still in pilot; ~10 million retail users; extended to subsidies (PDS) | AE22: 2026-10-01 | AF22: 2022 | AG22: 2022-02-01 | AH22: 2022-11-01 | AM22: 2026-10-01 | AO22: 0.0 | AP22: 19 pilot banks; ₹1,016 crore in circulation (Mar 2025) | AQ22: Large (≥10 lakh) | AU22: E2 | AV22: Environment | AW22: 2 | AX22: 5 | AY22: 5 – Official source with live/current data | AZ22: 9 | BA22: 4 | BB22: https://www.rbi.org.in/commonman/English/scripts/FAQs.aspx?Id=3686 | BC22: Do not call e₹ blockchain-based without RBI source | BE22: 2026-10-15
A23: O02 | B23: Blockchain letter-of-credit trade finance pilot | C23: Digital LCs to stop document tampering | D23: active | E23: Union | F23: Regulator / central bank | G23: RBI with SBI, HDFC Bank, ICICI Bank | H23: Central bank | I23: Other public body | J23: IN | K23: Union / national | L23: National | M23: National | O23: Finance & Payments | P23: 4 | Q23: Economic affairs | R23: Financial infrastructure | S23: Market transparency & settlement risk | T23: G2B | U23: Corda / IBM / SettleMint | V23: Corda / IBM | W23: Other enterprise DLT | X23: Permissioned | Y23: IBM, Corda, SettleMint | Z23: Private technology vendor | AA23: No | AB23: Pilot completed | AC23: Pilot completed | AD23: PoC stage reported | AE23: 2024-12-30 | AF23: 2022 | AG23: 2022-06-23 | AH23: 2022-06 | AI23: 2022-07 | AM23: 2024-12-30 | AO23: 1.8 | AQ23: Not reported | AU23: O3;T1 | AV23: Organisation;Technology | AW23: 2 | AX23: 4 | AY23: 4 – Official document (govt site, PIB, tender, court) | AZ23: 5 | BA23: 1 | BB23: https://rbihub.in/wp-content/uploads/2023/04/RBIH-Interoperable-DLT-PoC-Closure-Report.pdf | BE23: 2026-10-15
A24: O03 | B24: Invoice tokenisation for MSME supply-chain finance | C24: Tokenises accepted supplier invoices; lenders finance against tokens | D24: active | E24: Union | F24: Regulator / central bank | G24: RBI Regulatory Sandbox – IBDIC (bank-owned) | H24: Central bank | I24: Other public body | J24: IN | K24: Union / national | L24: National | M24: National | O24: Finance & Payments | P24: 4 | Q24: Economic affairs | R24: Financial infrastructure | S24: Market transparency & settlement risk | T24: G2B | U24: Not disclosed | V24: Not disclosed | W24: Not disclosed | X24: Not disclosed | Y24: ICICI, HDFC, Yes Bank, Aditya Birla Capital | Z24: Banks, depositories or telecom operators | AA24: No | AB24: Pilot completed | AC24: Pilot completed | AD24: Exited sandbox; may be adopted by regulated entities | AE24: 2025-08-27 | AF24: 2024 | AG24: 2024-07-26 | AH24: 2024-08 | AI24: 2025-08-14 | AM24: 2025-08-27 | AO24: 1.1 | AQ24: Not reported | AW24: 0 | AX24: 4 | AY24: 4 – Official document (govt site, PIB, tender, court) | AZ24: 4 | BA24: 2 | BB24: https://www.rbi.org.in/scripts/BS_PressReleaseDisplay.aspx?prid=58377 | BE24: 2026-10-15
A25: O04 | B25: Trade finance & payments PoCs | C25: Letter of credit and payment PoCs with banks | D25: active | E25: Union | F25: Regulator / central bank | G25: RBI – IDRBT | H25: Central bank (research arm) | I25: Other public body | J25: IN | K25: Union / national | L25: National | M25: National | O25: Finance & Payments | P25: 4 | Q25: Economic affairs | R25: Financial infrastructure | S25: Market transparency & settlement risk | T25: G2B | U25: Not stated | V25: Not disclosed | W25: Not disclosed | X25: Not disclosed | Y25: MonetaGo (with NPCI and banks) | Z25: Private technology vendor | AA25: No | AB25: Pilot completed | AC25: Pilot completed | AD25: PoCs completed | AE25: 2018 | AF25: 2017 | AG25: 2017-01 | AI25: 2017-01 | AM25: 2018 | AO25: 8.3 | AQ25: Not reported | AW25: 0 | AX25: 4 | AY25: 4 – Official document (govt site, PIB, tender, court) | AZ25: 5 | BA25: 1 | BB25: https://www.investindia.gov.in/team-india-blogs/implementing-blockchain-india | BE25: 2026-10-15
A26: O05 | B26: DLT security & covenant monitoring for NCDs | C26: Records asset charges, asset cover, covenants and ratings of debentures | D26: active | E26: Union | F26: Regulator / central bank | G26: SEBI with NSDL & CDSL | H26: Capital markets regulator | I26: Other public body | J26: IN | K26: Union / national | L26: National | M26: National | O26: Finance & Payments | P26: 4 | Q26: Economic affairs | R26: Financial infrastructure | S26: Market transparency & settlement risk | T26: G2B | U26: Permissioned DLT (2 depository nodes) | V26: Depository / regulator DLT | W26: Other enterprise DLT | X26: Permissioned | Y26: NSDL, CDSL | Z26: Banks, depositories or telecom operators | AA26: No | AB26: Implemented | AC26: Live | AD26: Mandatory and operational (NSDL 'DeLiTe' platform) | AE26: 2025-10-24 | AF26: 2021 | AG26: 2021-08-13 | AJ26: 2022-04-01 | AM26: 2025-10-24 | AN26: 8 | AO26: 1.0 | AP26: 550+ issuers; 3,800+ secured ISINs (~90% of outstanding) per deck | AQ26: Large (≥10 lakh) | AW26: 0 | AX26: 5 | AY26: 5 – Official source with live/current data | AZ26: 9 | BA26: 4 | BB26: https://www.pib.gov.in/PressReleasePage.aspx?PRID=2182023 | BC26: Deck cites Cognizant case study for numbers Cognizant case study (data as of 28 Nov 2024) reports 4,291 issuers and 6,368 secured ISINs, higher than the deck figures. | BE26: 2026-10-15
A27: O06 | B27: DLT for commercial SMS / telemarketing | C27: Senders and telemarketers register message chains; end-to-end SMS tracking | D27: active | E27: Union | F27: Regulator / central bank | G27: TRAI | H27: Telecom regulator | I27: Other public body | J27: IN | K27: Union / national | L27: National | M27: National | O27: Telecom & Cyber | P27: 4 | Q27: Economic affairs | R27: Authentication & anti-fraud | S27: Fraud / spam / fake apps | T27: G2B | U27: Permissioned DLT | V27: Depository / regulator DLT | W27: Other enterprise DLT | X27: Permissioned | Y27: Telcos, RBI, SEBI, NIC, C-DAC | Z27: Banks, depositories or telecom operators | AA27: No | AB27: Implemented | AC27: Live | AD27: Operational | AE27: 2025-10-24 | AF27: 2020 | AG27: 2018-07-19 | AJ27: 2021-03-08 | AK27: 2024-12-11 | AM27: 2025-10-24 | AN27: 32 | AO27: 1.0 | AP27: 1.13 lakh+ entities | AQ27: Large (≥10 lakh) | AU27: E2 | AV27: Environment | AW27: 2 | AX27: 5 | AY27: 5 – Official source with live/current data | AZ27: 6 | BA27: 4 | BB27: https://www.pib.gov.in/PressReleasePage.aspx?PRID=2182023 | BE27: 2026-10-15
A28: O07 | B28: Remote Voting Chain – PoC for migrant/in-service voters | C28: Encrypted remote votes stored on blockchain; only the parent-constituency returning officer can decrypt on counting day | D28: active | E28: Union | F28: Election commission | G28: Election Commission of India with NIC (and IIT Madras research) | H28: Constitutional body | I28: Other public body | J28: IN | K28: Union / national | L28: National | M28: National | O28: Elections | P28: 1 | Q28: General public services | R28: E-voting | S28: Voter access & vote integrity | T28: G2C | U28: Permissioned (NIC) | V28: NIC chains (Hyperledger-based) | W28: Hyperledger family | X28: Permissioned | Y28: NIC; IIT Madras | Z28: Government IT (NIC / C-DAC / NeGD) | AA28: Yes | AB28: Pilot completed | AC28: Pilot completed | AD28: PoC built per ECI directions and demonstrated; no rollout | AE28: 2022-01 | AF28: 2021 | AG28: 2020-02 | AM28: 2022-01 | AO28: 4.7 | AQ28: Not reported | AU28: E2;T3 | AV28: Environment;Technology | AW28: 2 | AX28: 4 | AY28: 4 – Official document (govt site, PIB, tender, court) | AZ28: 10 | BA28: 3 | BB28: https://blockchain.gov.in/Home/CaseStudy?CaseStudy=remotevotingchain | BE28: 2026-10-15
A29: O08 | B29: eCourts Phase III vision: digital signatures & blockchain for document authentication | C29: Vision document lists blockchain (with digital signatures) to secure and authenticate court documents | D29: active | E29: Union | F29: Court / judiciary | G29: Supreme Court of India – e-Committee | H29: Judiciary | I29: Other public body | J29: IN | K29: Union / national | L29: National | M29: National | O29: Justice & Police | P29: 3 | Q29: Public order and safety | R29: Records & audit trail | S29: Tampering of records | T29: G2C | U29: Not specified | V29: Not disclosed | W29: Not disclosed | X29: Not disclosed | Y29: — | Z29: Not applicable (policy or judgment) | AA29: No | AB29: Proposed / Planned | AC29: Planned | AD29: Proposed in vision; no blockchain-specific rollout published | AE29: 2025-12-19 | AF29: 2022 | AG29: 2022-09-23 | AM29: 2025-12-19 | AO29: 0.8 | AQ29: Not reported | AW29: 0 | AX29: 4 | AY29: 4 – Official document (govt site, PIB, tender, court) | AZ29: 6 | BA29: 4 | BB29: https://cdnbbsr.s3waas.gov.in/s35d6646aad9bcc0be55b2c82f69750387/uploads/2024/07/202407161620804267.pdf | BC29: Only one line in the vision document | BE29: 2026-10-15
A30: O09 | B30: Samiullah v. State of Bihar (2025 INSC 1292) – blockchain for land registration | C30: Bench suggested blockchain to make land registration tamper-proof; asked Law Commission to study reform and Union to set up a body with States | D30: active | E30: Union | F30: Court / judiciary | G30: Supreme Court of India (judgment) | H30: Judiciary | I30: Other public body | J30: IN | K30: Union / national | L30: National | M30: National | O30: Land & Property | P30: 1 | Q30: General public services | R30: Land / property registry | S30: Land fraud & disputes | T30: G2C | U30: — | V30: Not disclosed | W30: Not disclosed | X30: Not disclosed | Y30: — | Z30: Not applicable (policy or judgment) | AA30: No | AB30: Proposed / Planned | AC30: Planned | AD30: Judicial recommendation; Law Commission study requested | AE30: 2026-01-22 | AF30: 2025 | AG30: 2025-11-07 | AM30: 2026-01-22 | AO30: 0.7 | AP30: Property disputes ≈66% of civil cases (as cited) | AQ30: Not reported | AU30: E1;O4;T4 | AV30: Environment;Organisation;Technology | AW30: 3 | AX30: 4 | AY30: 4 – Official document (govt site, PIB, tender, court) | AZ30: 7 | BA30: 1 | BB30: https://www.lawcurb.in/judgements/samiullah-vs-the-state-of-bihar-&-ors-2025-insc-1292 | BE30: 2026-10-15
A31: O10 | B31: Asset tokenisation with wholesale CBDC settlement | C31: Tokenised certificates of deposit and bonds settled atomically in wholesale e₹ on a depository-run ledger | D31: active | E31: Union | F31: Regulator / central bank | G31: RBI with depositories – Unified Markets Interface (UMI) | H31: Central bank | I31: Other public body | J31: IN | K31: Union / national | L31: National | M31: National | O31: Finance & Payments | P31: 4 | Q31: Economic affairs | R31: Tokenisation / NFTs | S31: Asset liquidity / digital ownership | T31: G2B | U31: DLT run by depositories + wholesale CBDC | V31: Depository / regulator DLT | W31: Other enterprise DLT | X31: Permissioned | Y31: NSDL/CDSL; issuers incl. REC (state-owned) | Z31: Banks, depositories or telecom operators | AA31: No | AB31: In progress | AC31: In development | AD31: CD pilot (2025); bond pilot (Sep 2026) – REC ₹500 crore, L&T ₹500 crore, IIFL ₹25 crore | AE31: 2026-09-11 | AF31: 2025 | AG31: 2025-10-08 | AH31: 2025-10 | AM31: 2026-09-11 | AO31: 0.1 | AP31: ₹1,025 crore (~$107M) bond pilot | AQ31: Not reported | AW31: 0 | AX31: 4 | AY31: 4 – Official document (govt site, PIB, tender, court) | AZ31: 10 | BA31: 2 | BB31: https://www.bis.org/review/r251014b.pdf | BE31: 2026-10-15
A32: O11 | B32: Digi Yatra – paperless air travel with self-sovereign identity | C32: Face-based boarding; data encrypted, kept on passenger phone, blockchain used for storage (Minister) | D32: active | E32: Union | F32: Society / foundation | G32: DigiYatra Foundation (Ministry of Civil Aviation; AAI stakeholder) | H32: Ministry of Civil Aviation | I32: Other public body | J32: IN | K32: Union / national | L32: National | M32: National | O32: Certificates & Identity | P32: 1 | Q32: General public services | R32: Certificates & identity | S32: Identity verification & privacy | T32: G2C | U32: Hyperledger-based SSI (per deck) | V32: Hyperledger (other) | W32: Hyperledger family | X32: Permissioned | Y32: — | Z32: Private technology vendor | AA32: No | AB32: Implemented | AC32: Live | AD32: Live and expanding | AE32: 2026-09-21 | AF32: 2022 | AG32: 2018-10-04 | AI32: 2021-12-16 | AJ32: 2022-12-01 | AK32: 2024-09-06 | AM32: 2026-09-21 | AN32: 50 | AO32: 0.1 | AP32: 24 airports, 16 million users (deck, Dec 2025) | AQ32: Large (≥10 lakh) | AU32: E1;O3;O4;T3 | AV32: Environment;Organisation;Technology | AW32: 4 | AX32: 4 | AY32: 4 – Official document (govt site, PIB, tender, court) | AZ32: 9 | BA32: 4 | BB32: https://www.pib.gov.in/newsite/printrelease.aspx?relid=183958&reg=48&lang=2 | BE32: 2026-10-15
A33: O12 | B33: Blockchain traceability for Gir cow ghee (and Badri ghee) | C33: QR on pack shows farm-to-table journey; linked with Bharat Pashudhan traceability | D33: active | E33: Union | F33: Statutory board / authority | G33: NDDB / Mother Dairy with GS1 India | H33: Ministry of Cooperation / Dept of Animal Husbandry & Dairying | I33: Other public body | J33: IN | K33: Union / national | L33: National | M33: National | O33: Agriculture & Trade | P33: 4 | Q33: Economic affairs | R33: Supply-chain traceability | S33: Lack of traceability / counterfeits | T33: G2B | U33: Hyperledger Fabric (Spydra) | V33: Hyperledger Fabric | W33: Hyperledger family | X33: Permissioned | Y33: GS1 India, Spydra | Z33: Private technology vendor | AA33: No | AB33: Implemented | AC33: Live | AD33: Live; showcased in Republic Day 2025 tableau (per deck) | AE33: 2025-12 | AF33: 2024 | AG33: 2024-07-11 | AJ33: 2024-10-22 | AM33: 2025-12 | AN33: 3 | AO33: 0.8 | AP33: ~10,000 farmers; ~20,000 cattle (Junagadh) | AQ33: Medium (10,000–10 lakh) | AW33: 0 | AX33: 4 | AY33: 4 – Official document (govt site, PIB, tender, court) | AZ33: 6 | BA33: 3 | BB33: https://www.nddb.coop/node/2436 | BC33: NDDB page says 'Bharat Pashudhan'; blockchain per GS1/vendor | BE33: 2026-10-15
A34: O13 | B34: NFT souvenir train tickets (Holi 2024; MahaKumbh 2025) | C34: Travel to MahaKumbh recorded as verifiable NFT | D34: active | E34: Union | F34: PSU / state-owned company | G34: IRCTC (Ministry of Railways PSU) | H34: Ministry of Railways | I34: Other public body | J34: IN | K34: Union / national | L34: National | M34: National | O34: Transport | P34: 4 | Q34: Economic affairs | R34: Tokenisation / NFTs | S34: Digital souvenirs / ownership | T34: G2C | U34: Polygon (public) | V34: Polygon | W34: Ethereum / EVM chains | X34: Public | Y34: Chaincode Consulting, NFTtrace | Z34: Private technology vendor | AA34: No | AB34: Implemented | AC34: Live | AD34: Issued for events | AE34: 2025-01-13 | AF34: 2024 | AG34: 2024-03 | AJ34: 2024-03 | AM34: 2025-01-13 | AN34: 0 | AO34: 1.8 | AQ34: Not reported | AW34: 0 | AX34: 2 | AY34: 2 – Trade/crypto press or secondary (eBook, deck, blog) | AZ34: 3 | BA34: 0 | BB34: https://cointelegraph.com/news/indian-railways-nft-tickets-mahakumbh-mela | BE34: 2026-10-15
A35: O14 | B35: Academic documents on NIC Certificate Chain (cbse.certchain.nic.in) | C35: Tamper-proof academic records verifiable online | D35: active | E35: Union | F35: Statutory board / authority | G35: Central Board of Secondary Education (CBSE) | H35: Ministry of Education | I35: Other public body | J35: IN | K35: Union / national | L35: National | M35: National | O35: Education & Skills | P35: 9 | Q35: Education | R35: Certificates & identity | S35: Forgery / fake documents | T35: G2C | U35: Permissioned (NIC) | V35: NIC chains (Hyperledger-based) | W35: Hyperledger family | X35: Permissioned | Y35: NIC | Z35: Government IT (NIC / C-DAC / NeGD) | AA35: Yes | AB35: Implemented | AC35: Live | AD35: Live – 2nd largest NIC chain by documents | AE35: 2026-10-14 | AF35: 2019 | AG35: 2021-09-22 | AJ35: 2021-09-22 | AM35: 2026-10-14 | AN35: 0 | AO35: 0.0 | AP35: 2,10,71,556 documents; 85,261 verifications (NIC statistics, 2026-10-14) | AQ35: Large (≥10 lakh) | AR35: 21071556 | AS35: 85261 | AT35: 2026-10-14 | AW35: 0 | AX35: 5 | AY35: 5 – Official source with live/current data | AZ35: 7 | BA35: 6 | BB35: https://blockchain.gov.in/Home/Home | BE35: 2026-10-15
A36: O15 | B36: Blockchain digital degrees & certificates | C36: Forgery-proof, verifiable digital certificates (IIT Kanpur degrees, PM Bal Puraskar) and self-sovereign identity (SSI) ID cards for IITK employees | D36: active | E36: Union | F36: University / research institute | G36: IIT Kanpur – National Blockchain Project (NSCS-coordinated) | H36: Ministry of Education / NSCS | I36: Other public body | J36: IN | K36: Union / national | L36: National | M36: National | O36: Education & Skills | P36: 9 | Q36: Education | R36: Certificates & identity | S36: Forgery / fake documents | T36: G2C | U36: IIT Kanpur NBP platform | V36: IIT Kanpur NBP | W36: Other enterprise DLT | X36: Not disclosed | Y36: CRUBN | Z36: Academic / research partner | AA36: No | AB36: Implemented | AC36: Live | AD36: In use | AE36: 2025-12 | AF36: 2021 | AJ36: 2021-12-28 | AK36: 2022-01 | AM36: 2025-12 | AO36: 0.8 | AQ36: Not reported | AW36: 0 | AX36: 4 | AY36: 4 – Official document (govt site, PIB, tender, court) | AZ36: 8 | BA36: 4 | BB36: https://www.pib.gov.in/Pressreleaseshare.aspx?PRID=1785750&reg=3&lang=2 | BE36: 2026-10-15
A37: O16 | B37: Blockchain coffee e-marketplace | C37: Bean-to-cup traceability; fewer middlemen | D37: active | E37: Union | F37: Statutory board / authority | G37: Coffee Board of India | H37: Ministry of Commerce & Industry | I37: Other public body | J37: IN | K37: Union / national | L37: National | M37: National | O37: Agriculture & Trade | P37: 4 | Q37: Economic affairs | R37: Supply-chain traceability | S37: Lack of traceability / counterfeits | T37: G2B | U37: Ethereum | V37: Ethereum | W37: Ethereum / EVM chains | X37: Public | Y37: Eka Plus | Z37: Private technology vendor | AA37: No | AB37: Unclear (no recent update) | AC37: Unclear | AD37: Grew to ~30,000 farmers; no later status | AE37: 2021 | AF37: 2019 | AG37: 2019-03-28 | AH37: 2019-03-28 | AM37: 2021 | AO37: 5.3 | AP37: ~30,000 farmers | AQ37: Medium (10,000–10 lakh) | AU37: E2 | AV37: Environment | AW37: 1 | AX37: 2 | AY37: 2 – Trade/crypto press or secondary (eBook, deck, blog) | AZ37: 2 | BA37: 0 | BB37: https://www.ledgerinsights.com/blockchain-coffee-food-traceability-india/ | BE37: 2026-10-15
A38: O17 | B38: Spice traceability & trading (eSpiceBazaar) | C38: Traceability for chilli and turmeric with GS1 farm IDs, linked to e-Spice Bazaar | D38: active | E38: Union | F38: Statutory board / authority | G38: Spices Board with UNDP & GS1 India | H38: Ministry of Commerce & Industry | I38: Other public body | J38: IN | K38: Union / national | L38: National | M38: National | O38: Agriculture & Trade | P38: 4 | Q38: Economic affairs | R38: Supply-chain traceability | S38: Lack of traceability / counterfeits | T38: G2B | U38: Not stated | V38: Not disclosed | W38: Not disclosed | X38: Not disclosed | Y38: UNDP Accelerator Lab, GS1 India | Z38: International organisation | AA38: No | AB38: Unclear (no recent update) | AC38: Unclear | AD38: Pilot in select AP districts; no later status found | AE38: 2021-04-05 | AF38: 2021 | AG38: 2021-04-05 | AM38: 2021-04-05 | AO38: 5.5 | AP38: 3,000+ farmers (pilot) | AQ38: Small (<10,000) | AW38: 0 | AX38: 4 | AY38: 4 – Official document (govt site, PIB, tender, court) | AZ38: 2 | BA38: 1 | BB38: https://www.pib.gov.in/PressReleseDetailm.aspx?PRID=1709674&reg=3&lang=2 | BE38: 2026-10-15
A39: O18 | B39: Blockchain solutions with NIC (details not public) | C39: Named by MeitY as developing blockchain solutions | D39: active | E39: Union | F39: PSU / state-owned company | G39: UIDAI; SPMCIL; Cotton Corporation of India; Forensic Science Laboratory | H39: Various ministries | I39: Other public body | J39: IN | K39: Union / national | L39: National | M39: National | O39: Platform & Infrastructure | P39: 1 | Q39: General public services | R39: Platform / ecosystem | S39: Capacity & shared infrastructure | T39: G2G | U39: Not disclosed | V39: Not disclosed | W39: Not disclosed | X39: Not disclosed | Y39: NIC | Z39: Government IT (NIC / C-DAC / NeGD) | AA39: No | AB39: In progress | AC39: In development | AD39: Development stage | AE39: 2024-12-16 | AF39: 2024 | AG39: 2024-12 | AM39: 2024-12-16 | AO39: 1.8 | AQ39: Not reported | AW39: 0 | AX39: 3 | AY39: 3 – Mainstream news | AZ39: 1 | BA39: 0 | BB39: https://www.medianama.com/2024/12/223-blockchain-land-use-pilot-karnataka-jharkhandd/ | BC39: Scope not public | BE39: 2026-10-15
